Workbook

Sheet Cover
B3: PROJECT MEASURE
B4: Take-Private (LBO) Analysis — AISAN TECHNOLOGY CO., LTD.
B5: Tokyo Stock Exchange (Standard) · Ticker 4667 · Headquartered in Nagoya, Japan
B8: Deliverable | C8: Confidential LBO model & investment recommendation
B9: Prepared for | C9: Investment Committee (case study)
B10: Contact | C10: Ryuji Tomoe
B11: Currency | C11: Japanese Yen (¥), figures in millions unless noted
B12: Reference date | C12: Reference pricing as of 5-Jun-2026 (post-investigation news; re-base on clean price)
B13: Status | C13: Phase-1 screening — preliminary, public information only
B15: Contents
B16: 1. Assumptions | C16: Key transaction, financing & operating inputs (blue = editable)
B17: 2. Sources & Uses | C17: Funding structure and opening capitalization
B18: 3. Operating Model | C18: Revenue, margin and EBITDA build, FY24A–FY31E
B19: 4. Debt & FCF | C19: Free-cash-flow build, cash sweep, credit metrics & intra-year seasonality
B20: 5. Returns | C20: IRR / MOIC, value-creation bridge & sensitivities
B21: 6. Scenarios | C21: Base / Upside / Downside summary; illustrative LP net returns
B22: 7. Lev_Sensitivity | C22: Leverage cases (1.0x-3.0x), financing-policy sensitivities (sweep %, interest rate); supports walk-to-price
B23: DISCLAIMER — Illustrative analysis prepared for a case-study exercise. Based solely on public sources (company disclosure via EDINET/TDnet, IR materials, IRBANK). Figures in ¥mm unless stated. Estimates (D&A, capex, net cash at close, share count net of treasury) require confirmation in confirmatory due diligence. Not investment advice; not an offer or solicitation.

Sheet Assumptions
A1: 1 · KEY ASSUMPTIONS
A2: Blue = hardcoded input / scenario lever · Black = formula · Green = link from another sheet
B4: Transaction & entry valuation | F4: Financing structure
B5: Reference share price (¥, post-investigation disclosure) | C5: 1680 | D5: 5-Jun-26 close | F5: New senior debt / FY26E EBITDA (gross) | G5: 2 | H5: Gross senior; note (1)
B6: Shares outstanding (mm) | C6: =(5548979-268816)/1000000 -> 5.280163 | D6: less 268,816 treasury | F6: New senior debt (term loan) | G6: =G5*C19 -> 1600
B7: Offer premium to reference price | C7: 0.37 | D7: JP TOB 30-45% typical | F7: All-in interest rate on debt | G7: 0.035 | H7: TIBOR/TONA + spread; note (3)
B8: Offer price per share (¥) | C8: =C5*(1+C7) -> 2301.6 | F8: Cash sweep (% of FCF) | G8: 0.8 | H8: Mandatory + excess sweep; note (2)
B9: Equity purchase price | C9: =C8*C6 -> 12152.823 | D9: ¥mm | F9: Minimum operating cash | G9: 800 | H9: Seasonal WC buffer; note (6)
B10: (+) Existing gross debt | C10: 100 | D10: FY25A ¥51mm | F10: Transaction & financing fees | G10: 400 | H10: ~4-5% of EV (small-cap)
B11: (–) Cash & equivalents | C11: 4200 | D11: FY25A ¥4,176mm | F11: Excess cash used in funding | G11: =C11-G9 -> 3400 | H11: Cash less min cash; note (7)
B12: Net cash (–) / net debt (+) | C12: =C10-C11 -> -4100 | D12: Negative = net cash
B13: Implied Enterprise Value (EV) | C13: =C9+C12 -> 8052.8232 | F13: Tax & exit
F14: Effective tax rate | G14: 0.31 | H14: Japan statutory; note (8)
B15: Entry operating metrics (LTM = FY26E) | F15: Holding period (years) | G15: 5 | H15: Exit end-FY31E (Mar-2031)
B16: LTM revenue | C16: 7200 | D16: FY26E guidance; note (4) | F16: Exit EV / EBITDA multiple | G16: 10 | H16: Held ~flat vs entry; note (5)
B17: LTM EBIT (operating profit) | C17: 600 | D17: FY26E guidance; note (4)
B18: LTM D&A | C18: 200 | D18: Est. ~2.8% of sales | F18: Operating drivers (projection)
B19: LTM EBITDA | C19: =C17+C18 -> 800 | D19: EBIT + D&A; note (4) | F19: Driver | G19: FY27E | H19: FY28E | I19: FY29E | J19: FY30E
B20: Entry EV / LTM EBITDA | C20: =C13/C19 -> 10.066029 | F20: Revenue growth % | G20: 0.07 | H20: 0.07 | I20: 0.06 | J20: 0.06
B21: Entry EV / LTM EBIT | C21: =C13/C17 -> 13.421372 | F21: Revenue growth % (FY31E) | G21: 0.05
B22: Offer P / FY26E net income | C22: =C9/C23 -> 31.813673 | D22: FY26E NI ¥382mm | F22: EBIT margin % | G22: 0.092 | H22: 0.1 | I22: 0.108 | J22: 0.114
B23: FY26E net income (¥mm) | C23: 382 | D23: FY26E guidance | F23: EBIT margin % (FY31E) | G23: 0.12
F24: D&A (¥mm) | G24: 210 | H24: 220 | I24: 235 | J24: 250
F25: D&A (¥mm, FY31E) | G25: 265
F26: Capex (% of revenue) | G26: 0.025 | H26: ΔNWC % | I26: 0.06 | J26: of Δrevenue
B28: Premium reference points
B29: Last close (5-Jun-26) | C29: =C5 -> 1680 | D29: =C8/C29-1 -> 0.37
B30: Pre-announcement close (3-Apr-26) | C30: 1780 | D30: =C8/C30-1 -> 0.29303371
B31: 3-month VWAP | C31: 1739.7909 | D31: =C8/C31-1 -> 0.3229176
B32: 6-month VWAP | C32: 1928.8542 | D32: =C8/C32-1 -> 0.19324726
B33: Latest close (10-Jun-26; Tier IV listing-news spike) | C33: 1847 | D33: =$C$8/C33-1 -> 0.24612886
B34: NOTES ON KEY ASSUMPTIONS — sizing logic
A35: (1) | B35: Senior leverage: 2.0x gross on FY26E EBITDA = ¥1,600mm. Japanese senior LBO debt typically supports ~2-4x EBITDA; sized at the conservative end given the pending subsidiary investigation, delayed FY26 results and a small, lumpy EBITDA base. Net debt at close ~¥800mm (~1.0x net) after the minimum-cash buffer.
A36: (2) | B36: Cash sweep: 80% of FCF — standard mandatory-amortisation + excess-cash-sweep covenant; the retained 20% preserves capex / working-capital flexibility. Not a material return driver: 100% sweep lifts IRR by only ~2bp (16.77% vs 16.75%).
A37: (3) | B37: Interest: 3.5% all-in (TIBOR/TONA base + margin, post-BOJ normalisation), charged on beginning-of-year balances; no interest income on cash (conservative). +100bp / +200bp moves base IRR by only ~4bp / ~8bp at 2.0x (see Lev_Sensitivity).
A38: (4) | B38: EBITDA base: FY26E company guidance (revenue ¥7,200mm / OP ¥600mm, TDnet 27-Jan-2026) + estimated D&A, used as the LTM proxy because FY26 results disclosure is delayed by the investigation. Re-base on audited figures in confirmatory DD.
A39: (5) | B39: Exit multiple: 10.0x EV/EBITDA, held ~flat vs the 10.1x entry multiple — no multiple expansion underwritten.
A40: (6) | B40: Minimum operating cash: ¥800mm (~1.3 months of revenue) against the seasonal Q1-Q3 working-capital burn of public-sector-weighted revenue collection (Q4/March-end concentration).
A41: (7) | B41: Excess cash: ¥3,400mm (FY25A cash less minimum cash) part-funds the purchase; availability / extraction is a confirmatory-DD gate, not underwritten (see Returns cash-availability sensitivity).
A42: (8) | B42: Tax: 31% effective ≈ Japan statutory corporate rate; no NOLs or tax structuring assumed.
...

Sheet Sources_Uses
A1: 2 · SOURCES & USES OF FUNDS
A2: Funding of the take-private and opening (post-close) capitalization · ¥mm
B4: USES OF FUNDS | C4: ¥mm | D4: % | F4: SOURCES OF FUNDS | G4: ¥mm | H4: x EBITDA
B5: Purchase of equity | C5: =Assumptions!C9 -> 12152.823 | D5: =C5/$C$8 -> 0.96048313 | F5: New senior term loan | G5: =Assumptions!G6 -> 1600 | H5: =G5/Assumptions!C19 -> 2
B6: Repay existing debt | C6: =Assumptions!C10 -> 100 | D6: =C6/$C$8 -> 0.0079033745 | F6: Excess cash on balance sheet | G6: =Assumptions!G11 -> 3400
B7: Transaction & financing fees | C7: =Assumptions!G10 -> 400 | D7: =C7/$C$8 -> 0.031613498 | F7: Sponsor equity (plug) | G7: =C8-G5-G6 -> 7652.8232
B8: Total uses | C8: =SUM(C5:C7) -> 12652.823 | D8: =C8/$C$8 -> 1 | F8: Total sources | G8: =SUM(G5:G7) -> 12652.823
F10: Balance check (sources – uses) | G10: =G8-C8 -> 0
B11: OPENING (POST-CLOSE) CAPITALIZATION
B12: Senior term loan | C12: =G5 -> 1600 | F12: Aisan is net-cash (FY25A ≈ ¥4.1bn). Excess cash and low new debt give
B13: Cash (minimum operating) | C13: =Assumptions!G9 -> 800 | F13: approximately zero net debt at close; acquisition leverage is deliberately
B14: Net debt at close | C14: =C12-C13 -> 800 | F14: constrained pending QoE, investigation outcome, seasonality & lender diligence.
B15: Net debt / LTM EBITDA | C15: =C14/Assumptions!C19 -> 1
B16: Sponsor equity | C16: =G7 -> 7652.8232
B17: Equity % of total capitalization | C17: =C16/(C16+C12) -> 0.8270798
A19: Source: inputs per Assumptions (notes 1-8); structure illustrative pending financing commitments and DD on cash availability.

Sheet Model
A1: 3 · OPERATING MODEL
A2: Historical actuals (FY24A–FY26E) and base-case projection · ¥mm · FYE March
B4: Fiscal year (March) | C4: FY24A | D4: FY25A | E4: FY26E | F4: FY27E | G4: FY28E | H4: FY29E | I4: FY30E | J4: FY31E
B5: Revenue | C5: 5479 | D5: 6221 | E5: 7200 | F5: =E5*(1+Assumptions!G20) -> 7704 | G5: =F5*(1+Assumptions!H20) -> 8243.28 | H5: =G5*(1+Assumptions!I20) -> 8737.8768 | I5: =H5*(1+Assumptions!J20) -> 9262.1494 | J5: =I5*(1+Assumptions!G21) -> 9725.2569
B6: growth % | D6: =D5/C5-1 -> 0.13542617 | E6: =E5/D5-1 -> 0.1573702 | F6: =F5/E5-1 -> 0.07 | G6: =G5/F5-1 -> 0.07 | H6: =H5/G5-1 -> 0.06 | I6: =I5/H5-1 -> 0.06 | J6: =J5/I5-1 -> 0.05
B7: EBIT (operating profit) | C7: 450 | D7: 449 | E7: 600 | F7: =F5*Assumptions!G22 -> 708.768 | G7: =G5*Assumptions!H22 -> 824.328 | H7: =H5*Assumptions!I22 -> 943.69069 | I7: =I5*Assumptions!J22 -> 1055.885 | J7: =J5*Assumptions!G23 -> 1167.0308
B8: EBIT margin % | C8: =C7/C5 -> 0.082131776 | D8: =D7/D5 -> 0.072174891 | E8: =E7/E5 -> 0.083333333 | F8: =F7/F5 -> 0.092 | G8: =G7/G5 -> 0.1 | H8: =H7/H5 -> 0.108 | I8: =I7/I5 -> 0.114 | J8: =J7/J5 -> 0.12
B9: (+) Depreciation & amortization | C9: 200 | D9: 205 | E9: 200 | F9: =Assumptions!G24 -> 210 | G9: =Assumptions!H24 -> 220 | H9: =Assumptions!I24 -> 235 | I9: =Assumptions!J24 -> 250 | J9: =Assumptions!G25 -> 265
B10: EBITDA | C10: =C7+C9 -> 650 | D10: =D7+D9 -> 654 | E10: =E7+E9 -> 800 | F10: =F7+F9 -> 918.768 | G10: =G7+G9 -> 1044.328 | H10: =H7+H9 -> 1178.6907 | I10: =I7+I9 -> 1305.885 | J10: =J7+J9 -> 1432.0308
B11: EBITDA margin % | C11: =C10/C5 -> 0.11863479 | D11: =D10/D5 -> 0.10512779 | E11: =E10/E5 -> 0.11111111 | F11: =F10/F5 -> 0.11925857 | G11: =G10/G5 -> 0.12668841 | H11: =H10/H5 -> 0.13489441 | I11: =I10/I5 -> 0.14099157 | J11: =J10/J5 -> 0.14724864
B13: Segment context (FY26E estimate)
B14: Public (surveying & civil-engineering software) | E14: ~55-60% of sales | G14: ~20-26% margin — stable, recurring, gov-linked
B15: Mobility & DX (MMS, HD maps, autonomous driving) | E15: ~40-45% of sales | G15: Low / negative margin — lumpy, Q4-weighted, optionality
B16: Revenue concentrates in Q4 (Mar) as public projects close; Q1 is typically a loss.
B17: Source: company FY26 H1 results (TDnet, 12-Nov-2025); IRBANK. FY24A–FY25A per securities reports (EDINET).
B19: ILLUSTRATIVE SEGMENT ECONOMICS (FY26E) — reported / estimated; consolidated model is top-down
B20: Segment | C20: Rev share | D20: Segment margin | F20: Growth | G20: Value-up lever
B21: Public (surveying / civil-eng. software) | C21: ~55-60% | D21: ~26% (H1 FY26) | F21: +3-5% | G21: pricing, maintenance, software mix
B22: Mobility / DX (MMS, HD maps, AV) | C22: ~40-45% | D22: negative → breakeven | F22: +8-15% | G22: JV / partnership, selective investment
B23: Corporate / other | C23: n.m. | D23: cost drag | F23: n.m. | G23: overhead rationalisation
B24: Illustrative split per H1 FY26 reported segment data + estimates; to be verified in DD. Not a bottom-up driver of the consolidated projection above.

Sheet Debt_FCF
A1: 4 · FREE CASH FLOW & DEBT SCHEDULE
A2: Levered FCF, cash sweep and credit metrics over the holding period · ¥mm
B4: Fiscal year (March) | C4: FY24A | D4: FY25A | E4: FY26E | F4: FY27E | G4: FY28E | H4: FY29E | I4: FY30E | J4: FY31E
B5: EBIT | F5: =Model!F7 -> 708.768 | G5: =Model!G7 -> 824.328 | H5: =Model!H7 -> 943.69069 | I5: =Model!I7 -> 1055.885 | J5: =Model!J7 -> 1167.0308
B6: (–) Interest expense | F6: =-(F16)*Assumptions!G7 -> -56 | G6: =-(G16)*Assumptions!G7 -> -43.748042 | H6: =-(H16)*Assumptions!G7 -> -29.183524 | I6: =-(I16)*Assumptions!G7 -> -11.882682 | J6: =-(J16)*Assumptions!G7 -> 0
B7: Pre-tax income | F7: =F5+F6 -> 652.768 | G7: =G5+G6 -> 780.57996 | H7: =H5+H6 -> 914.50717 | I7: =I5+I6 -> 1044.0024 | J7: =J5+J6 -> 1167.0308
B8: (–) Tax | F8: =-MAX(0,F7)*Assumptions!G14 -> -202.35808 | G8: =-MAX(0,G7)*Assumptions!G14 -> -241.97979 | H8: =-MAX(0,H7)*Assumptions!G14 -> -283.49722 | I8: =-MAX(0,I7)*Assumptions!G14 -> -323.64073 | J8: =-MAX(0,J7)*Assumptions!G14 -> -361.77956
B9: Net income | F9: =F7+F8 -> 450.40992 | G9: =G7+G8 -> 538.60017 | H9: =H7+H8 -> 631.00995 | I9: =I7+I8 -> 720.36162 | J9: =J7+J8 -> 805.25127
B10: (+) D&A | F10: =Model!F9 -> 210 | G10: =Model!G9 -> 220 | H10: =Model!H9 -> 235 | I10: =Model!I9 -> 250 | J10: =Model!J9 -> 265
B11: (–) Capex | F11: =-Model!F5*Assumptions!G26 -> -192.6 | G11: =-Model!G5*Assumptions!G26 -> -206.082 | H11: =-Model!H5*Assumptions!G26 -> -218.44692 | I11: =-Model!I5*Assumptions!G26 -> -231.55374 | J11: =-Model!J5*Assumptions!G26 -> -243.13142
B12: (–) Increase in net working capital | F12: =-(Model!F5-Model!E5)*Assumptions!I26 -> -30.24 | G12: =-(Model!G5-Model!F5)*Assumptions!I26 -> -32.3568 | H12: =-(Model!H5-Model!G5)*Assumptions!I26 -> -29.675808 | I12: =-(Model!I5-Model!H5)*Assumptions!I26 -> -31.456356 | J12: =-(Model!J5-Model!I5)*Assumptions!I26 -> -27.786448
B13: Free cash flow (after interest & tax) | F13: =F9+F10+F11+F12 -> 437.56992 | G13: =G9+G10+G11+G12 -> 520.16137 | H13: =H9+H10+H11+H12 -> 617.88722 | I13: =I9+I10+I11+I12 -> 707.35153 | J13: =J9+J10+J11+J12 -> 799.3334
B15: SENIOR DEBT SCHEDULE
B16: Beginning balance | F16: =Sources_Uses!G5 -> 1600 | G16: =F18 -> 1249.9441 | H16: =G18 -> 833.81497 | I16: =H18 -> 339.50519 | J16: =I18 -> 0
B17: (–) Debt paydown (cash sweep) | F17: =-MIN(F16,MAX(0,F13)*Assumptions!G8) -> -350.05594 | G17: =-MIN(G16,MAX(0,G13)*Assumptions!G8) -> -416.1291 | H17: =-MIN(H16,MAX(0,H13)*Assumptions!G8) -> -494.30978 | I17: =-MIN(I16,MAX(0,I13)*Assumptions!G8) -> -339.50519 | J17: =-MIN(J16,MAX(0,J13)*Assumptions!G8) -> 0
B18: Ending balance | F18: =F16+F17 -> 1249.9441 | G18: =G16+G17 -> 833.81497 | H18: =H16+H17 -> 339.50519 | I18: =I16+I17 -> 0 | J18: =J16+J17 -> 0
B20: FCF retained in cash (after sweep) | F20: =MAX(0,F13)+F17 -> 87.513984 | G20: =MAX(0,G13)+G17 -> 104.03227 | H20: =MAX(0,H13)+H17 -> 123.57744 | I20: =MAX(0,I13)+I17 -> 367.84634 | J20: =MAX(0,J13)+J17 -> 799.3334
B21: Cash balance (end of year) | F21: =Assumptions!G9+F20 -> 887.51398 | G21: =F21+G20 -> 991.54626 | H21: =G21+H20 -> 1115.1237 | I21: =H21+I20 -> 1482.97 | J21: =I21+J20 -> 2282.3034
B22: Net debt (end of year) | F22: =F18-F21 -> 362.43008 | G22: =G18-G21 -> -157.73129 | H22: =H18-H21 -> -775.61851 | I22: =I18-I21 -> -1482.97 | J22: =J18-J21 -> -2282.3034
B24: CREDIT METRICS
B25: Net debt / EBITDA | F25: =F22/Model!F10 -> 0.39447399 | G25: =G22/Model!G10 -> -0.15103616 | H25: =H22/Model!H10 -> -0.65803396 | I25: =I22/Model!I10 -> -1.1356054 | J25: =J22/Model!J10 -> -1.593753
B26: EBITDA / interest | F26: =IFERROR(Model!F10/-F6,"n.m.") -> 16.406571 | G26: =IFERROR(Model!G10/-G6,"n.m.") -> 23.871423 | H26: =IFERROR(Model!H10/-H6,"n.m.") -> 40.388909 | I26: =IFERROR(Model!I10/-I6,"n.m.") -> 109.89817 | J26: =IFERROR(Model!J10/-J6,"n.m.") -> n.m.
B27: FCF / beginning debt (cash yield) | F27: =IFERROR(F13/F16,"n.m.") -> 0.2734812 | G27: =IFERROR(G13/G16,"n.m.") -> 0.41614772 | H27: =IFERROR(H13/H16,"n.m.") -> 0.74103637 | I27: =IFERROR(I13/I16,"n.m.") -> 2.0834778 | J27: =IFERROR(J13/J16,"n.m.") -> n.m.
B28: Gross debt / EBITDA | F28: =IFERROR(F18/Model!F10,"n.m.") -> 1.3604567 | G28: =IFERROR(G18/Model!G10,"n.m.") -> 0.79842249 | H28: =IFERROR(H18/Model!H10,"n.m.") -> 0.28803586 | I28: =IFERROR(I18/Model!I10,"n.m.") -> 0 | J28: =IFERROR(J18/Model!J10,"n.m.") -> 0
B32: INTRA-YEAR SEASONALITY — illustrative quarterly phasing (FY27E)
C33: Q1 | D33: Q2 | E33: Q3 | F33: Q4 | G33: FY27E
B34: Revenue phasing (% of year) | C34: 0.15 | D34: 0.2 | E34: 0.25 | F34: 0.4 | G34: =SUM(C34:F34) -> 1
B35: Revenue (¥mm) | C35: =C34*Model!$F$5 -> 1155.6 | D35: =D34*Model!$F$5 -> 1540.8 | E35: =E34*Model!$F$5 -> 1926 | F35: =F34*Model!$F$5 -> 3081.6 | G35: =SUM(C35:F35) -> 7704
B36: Operating costs (even spread) | C36: =-(Model!$F$5-Model!$F$10)/4 -> -1696.308 | D36: =-(Model!$F$5-Model!$F$10)/4 -> -1696.308 | E36: =-(Model!$F$5-Model!$F$10)/4 -> -1696.308 | F36: =-(Model!$F$5-Model!$F$10)/4 -> -1696.308 | G36: =SUM(C36:F36) -> -6785.232
B37: EBITDA (¥mm) | C37: =C35+C36 -> -540.708 | D37: =D35+D36 -> -155.508 | E37: =E35+E36 -> 229.692 | F37: =F35+F36 -> 1385.292 | G37: =SUM(C37:F37) -> 918.768
B38: Interest, tax, capex, ΔNWC (even) | C38: =($F$6+$F$8+$F$11+$F$12)/4 -> -120.29952 | D38: =($F$6+$F$8+$F$11+$F$12)/4 -> -120.29952 | E38: =($F$6+$F$8+$F$11+$F$12)/4 -> -120.29952 | F38: =($F$6+$F$8+$F$11+$F$12)/4 -> -120.29952 | G38: =SUM(C38:F38) -> -481.19808
B39: Cash balance (from ¥800mm floor) | C39: =Assumptions!G9+C37+C38 -> 138.99248 | D39: =C39+D37+D38 -> -136.81504 | E39: =D39+E37+E38 -> -27.42256 | F39: =E39+F37+F38 -> 1237.5699 | G39: =F39 -> 1237.5699 | H39: =MIN(C39:F39) -> -136.81504 | I39: min (trough)
B41: Even-cost phasing puts the trough ~¥0.1bn below zero at H1-end (Q2) — arrange a working-capital RCF (~¥0.5bn) and verify actual quarterly phasing in DD.
B42: Year-end ties to the debt schedule: Q4 cash + sweep (¥350mm) = year-end cash balance (¥888mm).
A44: Source: model-derived from Assumptions; sweep & interest mechanics per Assumptions notes (2)/(3); quarterly phasing illustrative (blue).

Sheet Returns
A1: 5 · RETURNS ANALYSIS
A2: Base-case IRR / MOIC, value-creation bridge and sensitivities · ¥mm
B4: EXIT (END FY31E · MAR-2031) | F4: VALUE-CREATION BRIDGE (equity, ¥mm)
B5: Exit EBITDA (FY31E) | C5: =Model!J10 -> 1432.0308 | F5: Entry equity | J5: =Sources_Uses!G7 -> 7652.8232
B6: Exit EV / EBITDA multiple | C6: =Assumptions!G16 -> 10 | F6: EBITDA growth (at entry multiple) | J6: =(Model!J10-Assumptions!C19)*Assumptions!C13/Assumptions!C19 -> 6362.0406
B7: Exit enterprise value | C7: =C5*C6 -> 14320.308 | F7: Multiple change (on exit EBITDA) | J7: =(Assumptions!G16-Assumptions!C13/Assumptions!C19)*Model!J10 -> -94.555493
B8: (–) Net debt / (+) net cash at exit | C8: =-Debt_FCF!J22 -> 2282.3034 | F8: Deleveraging, FCF & fees (net) | J8: =(Sources_Uses!C14-Debt_FCF!J22)-(Sources_Uses!G7-(Assumptions!C13-Sources_Uses!C14)) -> 2682.3034
B9: Exit equity value to sponsor | C9: =C7+C8 -> 16602.612 | F9: Exit equity value | J9: =SUM(J5:J8) -> 16602.612
F10: (reconciles to exit equity at left, C9)
B11: RETURNS
B12: Sponsor equity invested (entry) | C12: =Sources_Uses!G7 -> 7652.8232
B13: Equity value at exit | C13: =C9 -> 16602.612
B14: Holding period (years) | C14: =Assumptions!G15 -> 5
B15: MOIC (x) | C15: =C13/C12 -> 2.1694754
B16: Gross IRR (%) | C16: =(C13/C12)^(1/C14)-1 -> 0.16753779 | D16: ← single entry / single exit
B19: SENSITIVITY — Gross IRR
B20: Rows: offer premium · Columns: exit EV/EBITDA · base operating case held constant
E21: IRR | F21: 8 | G21: 9 | H21: 10 | I21: 11 | J21: 12
E22: 0.25 | F22: =((F$21*Model!J10+(-Debt_FCF!J22))/(Assumptions!C5*(1+$E22)*Assumptions!C6+(Assumptions!C10+Assumptions!G10)-(Sources_Uses!G5+Assumptions!G11)))^(1/Assumptions!G15)-1 -> 0.15833172 | G22: =((G$21*Model!J10+(-Debt_FCF!J22))/(Assumptions!C5*(1+$E22)*Assumptions!C6+(Assumptions!C10+Assumptions!G10)-(Sources_Uses!G5+Assumptions!G11)))^(1/Assumptions!G15)-1 -> 0.18153125 | H22: =((H$21*Model!J10+(-Debt_FCF!J22))/(Assumptions!C5*(1+$E22)*Assumptions!C6+(Assumptions!C10+Assumptions!G10)-(Sources_Uses!G5+Assumptions!G11)))^(1/Assumptions!G15)-1 -> 0.20303995 | I22: =((I$21*Model!J10+(-Debt_FCF!J22))/(Assumptions!C5*(1+$E22)*Assumptions!C6+(Assumptions!C10+Assumptions!G10)-(Sources_Uses!G5+Assumptions!G11)))^(1/Assumptions!G15)-1 -> 0.22311214 | J22: =((J$21*Model!J10+(-Debt_FCF!J22))/(Assumptions!C5*(1+$E22)*Assumptions!C6+(Assumptions!C10+Assumptions!G10)-(Sources_Uses!G5+Assumptions!G11)))^(1/Assumptions!G15)-1 -> 0.24194716
E23: 0.3 | F23: =((F$21*Model!J10+(-Debt_FCF!J22))/(Assumptions!C5*(1+$E23)*Assumptions!C6+(Assumptions!C10+Assumptions!G10)-(Sources_Uses!G5+Assumptions!G11)))^(1/Assumptions!G15)-1 -> 0.14333616 | G23: =((G$21*Model!J10+(-Debt_FCF!J22))/(Assumptions!C5*(1+$E23)*Assumptions!C6+(Assumptions!C10+Assumptions!G10)-(Sources_Uses!G5+Assumptions!G11)))^(1/Assumptions!G15)-1 -> 0.16623535 | H23: =((H$21*Model!J10+(-Debt_FCF!J22))/(Assumptions!C5*(1+$E23)*Assumptions!C6+(Assumptions!C10+Assumptions!G10)-(Sources_Uses!G5+Assumptions!G11)))^(1/Assumptions!G15)-1 -> 0.18746561 | I23: =((I$21*Model!J10+(-Debt_FCF!J22))/(Assumptions!C5*(1+$E23)*Assumptions!C6+(Assumptions!C10+Assumptions!G10)-(Sources_Uses!G5+Assumptions!G11)))^(1/Assumptions!G15)-1 -> 0.20727795 | J23: =((J$21*Model!J10+(-Debt_FCF!J22))/(Assumptions!C5*(1+$E23)*Assumptions!C6+(Assumptions!C10+Assumptions!G10)-(Sources_Uses!G5+Assumptions!G11)))^(1/Assumptions!G15)-1 -> 0.22586913
E24: 0.35 | F24: =((F$21*Model!J10+(-Debt_FCF!J22))/(Assumptions!C5*(1+$E24)*Assumptions!C6+(Assumptions!C10+Assumptions!G10)-(Sources_Uses!G5+Assumptions!G11)))^(1/Assumptions!G15)-1 -> 0.12943484 | G24: =((G$21*Model!J10+(-Debt_FCF!J22))/(Assumptions!C5*(1+$E24)*Assumptions!C6+(Assumptions!C10+Assumptions!G10)-(Sources_Uses!G5+Assumptions!G11)))^(1/Assumptions!G15)-1 -> 0.15205561 | H24: =((H$21*Model!J10+(-Debt_FCF!J22))/(Assumptions!C5*(1+$E24)*Assumptions!C6+(Assumptions!C10+Assumptions!G10)-(Sources_Uses!G5+Assumptions!G11)))^(1/Assumptions!G15)-1 -> 0.17302774 | I24: =((I$21*Model!J10+(-Debt_FCF!J22))/(Assumptions!C5*(1+$E24)*Assumptions!C6+(Assumptions!C10+Assumptions!G10)-(Sources_Uses!G5+Assumptions!G11)))^(1/Assumptions!G15)-1 -> 0.19259918 | J24: =((J$21*Model!J10+(-Debt_FCF!J22))/(Assumptions!C5*(1+$E24)*Assumptions!C6+(Assumptions!C10+Assumptions!G10)-(Sources_Uses!G5+Assumptions!G11)))^(1/Assumptions!G15)-1 -> 0.21096432
E25: 0.4 | F25: =((F$21*Model!J10+(-Debt_FCF!J22))/(Assumptions!C5*(1+$E25)*Assumptions!C6+(Assumptions!C10+Assumptions!G10)-(Sources_Uses!G5+Assumptions!G11)))^(1/Assumptions!G15)-1 -> 0.11648973 | G25: =((G$21*Model!J10+(-Debt_FCF!J22))/(Assumptions!C5*(1+$E25)*Assumptions!C6+(Assumptions!C10+Assumptions!G10)-(Sources_Uses!G5+Assumptions!G11)))^(1/Assumptions!G15)-1 -> 0.13885123 | H25: =((H$21*Model!J10+(-Debt_FCF!J22))/(Assumptions!C5*(1+$E25)*Assumptions!C6+(Assumptions!C10+Assumptions!G10)-(Sources_Uses!G5+Assumptions!G11)))^(1/Assumptions!G15)-1 -> 0.15958299 | I25: =((I$21*Model!J10+(-Debt_FCF!J22))/(Assumptions!C5*(1+$E25)*Assumptions!C6+(Assumptions!C10+Assumptions!G10)-(Sources_Uses!G5+Assumptions!G11)))^(1/Assumptions!G15)-1 -> 0.17893011 | J25: =((J$21*Model!J10+(-Debt_FCF!J22))/(Assumptions!C5*(1+$E25)*Assumptions!C6+(Assumptions!C10+Assumptions!G10)-(Sources_Uses!G5+Assumptions!G11)))^(1/Assumptions!G15)-1 -> 0.19708476
E26: 0.45 | F26: =((F$21*Model!J10+(-Debt_FCF!J22))/(Assumptions!C5*(1+$E26)*Assumptions!C6+(Assumptions!C10+Assumptions!G10)-(Sources_Uses!G5+Assumptions!G11)))^(1/Assumptions!G15)-1 -> 0.10438676 | G26: =((G$21*Model!J10+(-Debt_FCF!J22))/(Assumptions!C5*(1+$E26)*Assumptions!C6+(Assumptions!C10+Assumptions!G10)-(Sources_Uses!G5+Assumptions!G11)))^(1/Assumptions!G15)-1 -> 0.12650586 | H26: =((H$21*Model!J10+(-Debt_FCF!J22))/(Assumptions!C5*(1+$E26)*Assumptions!C6+(Assumptions!C10+Assumptions!G10)-(Sources_Uses!G5+Assumptions!G11)))^(1/Assumptions!G15)-1 -> 0.14701288 | I26: =((I$21*Model!J10+(-Debt_FCF!J22))/(Assumptions!C5*(1+$E26)*Assumptions!C6+(Assumptions!C10+Assumptions!G10)-(Sources_Uses!G5+Assumptions!G11)))^(1/Assumptions!G15)-1 -> 0.16615028 | J26: =((J$21*Model!J10+(-Debt_FCF!J22))/(Assumptions!C5*(1+$E26)*Assumptions!C6+(Assumptions!C10+Assumptions!G10)-(Sources_Uses!G5+Assumptions!G11)))^(1/Assumptions!G15)-1 -> 0.18410812
B28: MOIC sensitivity
E29: MOIC | F29: 8 | G29: 9 | H29: 10 | I29: 11 | J29: 12
E30: 0.25 | F30: =(F$29*Model!J10+(-Debt_FCF!J22))/(Assumptions!C5*(1+$E30)*Assumptions!C6+(Assumptions!C10+Assumptions!G10)-(Sources_Uses!G5+Assumptions!G11)) -> 2.0852818 | G30: =(G$29*Model!J10+(-Debt_FCF!J22))/(Assumptions!C5*(1+$E30)*Assumptions!C6+(Assumptions!C10+Assumptions!G10)-(Sources_Uses!G5+Assumptions!G11)) -> 2.3026401 | H30: =(H$29*Model!J10+(-Debt_FCF!J22))/(Assumptions!C5*(1+$E30)*Assumptions!C6+(Assumptions!C10+Assumptions!G10)-(Sources_Uses!G5+Assumptions!G11)) -> 2.5199983 | I30: =(I$29*Model!J10+(-Debt_FCF!J22))/(Assumptions!C5*(1+$E30)*Assumptions!C6+(Assumptions!C10+Assumptions!G10)-(Sources_Uses!G5+Assumptions!G11)) -> 2.7373566 | J30: =(J$29*Model!J10+(-Debt_FCF!J22))/(Assumptions!C5*(1+$E30)*Assumptions!C6+(Assumptions!C10+Assumptions!G10)-(Sources_Uses!G5+Assumptions!G11)) -> 2.9547149
E31: 0.3 | F31: =(F$29*Model!J10+(-Debt_FCF!J22))/(Assumptions!C5*(1+$E31)*Assumptions!C6+(Assumptions!C10+Assumptions!G10)-(Sources_Uses!G5+Assumptions!G11)) -> 1.9537532 | G31: =(G$29*Model!J10+(-Debt_FCF!J22))/(Assumptions!C5*(1+$E31)*Assumptions!C6+(Assumptions!C10+Assumptions!G10)-(Sources_Uses!G5+Assumptions!G11)) -> 2.1574017 | H31: =(H$29*Model!J10+(-Debt_FCF!J22))/(Assumptions!C5*(1+$E31)*Assumptions!C6+(Assumptions!C10+Assumptions!G10)-(Sources_Uses!G5+Assumptions!G11)) -> 2.3610501 | I31: =(I$29*Model!J10+(-Debt_FCF!J22))/(Assumptions!C5*(1+$E31)*Assumptions!C6+(Assumptions!C10+Assumptions!G10)-(Sources_Uses!G5+Assumptions!G11)) -> 2.5646986 | J31: =(J$29*Model!J10+(-Debt_FCF!J22))/(Assumptions!C5*(1+$E31)*Assumptions!C6+(Assumptions!C10+Assumptions!G10)-(Sources_Uses!G5+Assumptions!G11)) -> 2.7683471
E32: 0.35 | F32: =(F$29*Model!J10+(-Debt_FCF!J22))/(Assumptions!C5*(1+$E32)*Assumptions!C6+(Assumptions!C10+Assumptions!G10)-(Sources_Uses!G5+Assumptions!G11)) -> 1.8378324 | G32: =(G$29*Model!J10+(-Debt_FCF!J22))/(Assumptions!C5*(1+$E32)*Assumptions!C6+(Assumptions!C10+Assumptions!G10)-(Sources_Uses!G5+Assumptions!G11)) -> 2.0293979 | H32: =(H$29*Model!J10+(-Debt_FCF!J22))/(Assumptions!C5*(1+$E32)*Assumptions!C6+(Assumptions!C10+Assumptions!G10)-(Sources_Uses!G5+Assumptions!G11)) -> 2.2209635 | I32: =(I$29*Model!J10+(-Debt_FCF!J22))/(Assumptions!C5*(1+$E32)*Assumptions!C6+(Assumptions!C10+Assumptions!G10)-(Sources_Uses!G5+Assumptions!G11)) -> 2.412529 | J32: =(J$29*Model!J10+(-Debt_FCF!J22))/(Assumptions!C5*(1+$E32)*Assumptions!C6+(Assumptions!C10+Assumptions!G10)-(Sources_Uses!G5+Assumptions!G11)) -> 2.6040945
E33: 0.4 | F33: =(F$29*Model!J10+(-Debt_FCF!J22))/(Assumptions!C5*(1+$E33)*Assumptions!C6+(Assumptions!C10+Assumptions!G10)-(Sources_Uses!G5+Assumptions!G11)) -> 1.7348969 | G33: =(G$29*Model!J10+(-Debt_FCF!J22))/(Assumptions!C5*(1+$E33)*Assumptions!C6+(Assumptions!C10+Assumptions!G10)-(Sources_Uses!G5+Assumptions!G11)) -> 1.915733 | H33: =(H$29*Model!J10+(-Debt_FCF!J22))/(Assumptions!C5*(1+$E33)*Assumptions!C6+(Assumptions!C10+Assumptions!G10)-(Sources_Uses!G5+Assumptions!G11)) -> 2.0965691 | I33: =(I$29*Model!J10+(-Debt_FCF!J22))/(Assumptions!C5*(1+$E33)*Assumptions!C6+(Assumptions!C10+Assumptions!G10)-(Sources_Uses!G5+Assumptions!G11)) -> 2.2774052 | J33: =(J$29*Model!J10+(-Debt_FCF!J22))/(Assumptions!C5*(1+$E33)*Assumptions!C6+(Assumptions!C10+Assumptions!G10)-(Sources_Uses!G5+Assumptions!G11)) -> 2.4582413
E34: 0.45 | F34: =(F$29*Model!J10+(-Debt_FCF!J22))/(Assumptions!C5*(1+$E34)*Assumptions!C6+(Assumptions!C10+Assumptions!G10)-(Sources_Uses!G5+Assumptions!G11)) -> 1.6428804 | G34: =(G$29*Model!J10+(-Debt_FCF!J22))/(Assumptions!C5*(1+$E34)*Assumptions!C6+(Assumptions!C10+Assumptions!G10)-(Sources_Uses!G5+Assumptions!G11)) -> 1.8141253 | H34: =(H$29*Model!J10+(-Debt_FCF!J22))/(Assumptions!C5*(1+$E34)*Assumptions!C6+(Assumptions!C10+Assumptions!G10)-(Sources_Uses!G5+Assumptions!G11)) -> 1.9853701 | I34: =(I$29*Model!J10+(-Debt_FCF!J22))/(Assumptions!C5*(1+$E34)*Assumptions!C6+(Assumptions!C10+Assumptions!G10)-(Sources_Uses!G5+Assumptions!G11)) -> 2.1566149 | J34: =(J$29*Model!J10+(-Debt_FCF!J22))/(Assumptions!C5*(1+$E34)*Assumptions!C6+(Assumptions!C10+Assumptions!G10)-(Sources_Uses!G5+Assumptions!G11)) -> 2.3278597
B37: WALK-TO-PRICE — max offer clearing the IRR hurdle (base operating case)
B38: Hurdle gross IRR | C38: 0.2
B39: Exit equity (base) | C39: =C9 -> 16602.612
B40: Max sponsor equity | C40: =C39/(1+C38)^C14 -> 6672.2173
B41: Max equity purchase price | C41: =C40+Sources_Uses!G5+Assumptions!G11-Assumptions!G10-Assumptions!C10 -> 11172.217
B42: Max offer per share (¥) | C42: =C41/Assumptions!C6 -> 2115.8849
B43: Implied premium vs reference | C43: =C42/Assumptions!C5-1 -> 0.25945531
B44: Implied premium vs 6m VWAP | C44: =C42/Assumptions!C32-1 -> 0.096964668
B47: CASH AVAILABILITY SENSITIVITY — excess-cash extraction is a DD item, not underwritten
B48: Case | C48: Sponsor eq. | D48: Exit eq. | E48: MOIC | F48: Gross IRR
...

Sheet Scenarios
A1: 6 · SCENARIO SUMMARY
A2: Base case links to the live model; Upside / Downside use the same return engine with documented inputs · ¥mm
B4: Driver / output | C4: Downside | D4: Base | E4: Upside
B5: Revenue CAGR (entry→exit) | C5: 0.03 | D5: =(Model!J5/Model!E5)^(1/Assumptions!G15)-1 -> 0.061973591 | E5: 0.08 | G5: Scenario logic
B6: Exit EBITDA margin | C6: 0.115 | D6: =Model!J10/Model!J5 -> 0.14724864 | E6: 0.16 | G6: Downside: public budgets soften, Mobility/DX stays loss-making; flat margins, multiple de-rates to 8x. ≈ capital preservation.
B7: Exit EBITDA (¥mm) | C7: 960 | D7: =Model!J10 -> 1432.0308 | E7: 1690 | G7: Base: mid-single-digit growth, gradual margin lift to 12% via mix & cost discipline; exit 10x; returns remain below a clean 20% hurdle.
B8: Exit EV/EBITDA | C8: 8 | D8: =Assumptions!G16 -> 10 | E8: 11.5 | G8: Upside: Mobility/DX turns profitable & scales (Level-4 AV / HD-map tailwind), margin to ~16%, strategic exit at 11.5x, securities monetized.
B9: Net cash (+)/debt(–) at exit | C9: -500 | D9: =-Debt_FCF!J22 -> 2282.3034 | E9: 2000
B10: Entry sponsor equity | C10: =Sources_Uses!G7 -> 7652.8232 | D10: =Sources_Uses!G7 -> 7652.8232 | E10: =Sources_Uses!G7 -> 7652.8232 | G10: Key insight: even a modestly levered (2.0x gross senior) take-private remains below a typical 20%+ PE hurdle. The case rests on DD-cleared value-up levers
G11: (balance-sheet optimization, margin expansion, and a strategic re-rating of the autonomous-driving / HD-map franchise).
B12: Exit equity value | C12: =C7*C8+C9 -> 7180 | D12: =D7*D8+D9 -> 16602.612 | E12: =E7*E8+E9 -> 21435
B13: MOIC (x) | C13: =C12/C10 -> 0.93821585 | D13: =D12/D10 -> 2.1694754 | E13: =E12/E10 -> 2.8009271
B14: Gross IRR (%) | C14: =(C12/C10)^(1/Assumptions!G15)-1 -> -0.012674047 | D14: =(D12/D10)^(1/Assumptions!G15)-1 -> 0.16753779 | E14: =(E12/E10)^(1/Assumptions!G15)-1 -> 0.22874103
A18: ILLUSTRATIVE NET RETURNS TO LPs — fund economics applied to the base case
B19: Gross exit equity (base, ¥mm) | C19: =Returns!C9 -> 16602.612
B20: MIP dilution | C20: =Returns!B56 -> 0.05
B21: Management fee (p.a., × 5 yrs) | C21: 0.02
B22: Carried interest | C22: 0.2
B23: Preferred return (p.a.) | C23: 0.08
B24: Carried interest (¥mm) | C24: =MAX(0,(C19*(1-C20)-Returns!C12)-Returns!C12*((1+C23)^Returns!C14-1))*C22 -> 905.59463
B25: Management fees (¥mm) | C25: =Returns!C12*C21*Returns!C14 -> 765.28232
B26: Net proceeds to LPs (¥mm) | C26: =C19*(1-C20)-C24-C25 -> 14101.604
B27: Net MOIC / Net IRR | C27: =C26/Returns!C12 -> 1.8426669 | D27: =(C26/Returns!C12)^(1/Returns!C14)-1 -> 0.13002843
A29: Illustrative 2/20-style economics with an 8% pref and 5% MIP; fee base simplified to invested equity. Net ~1.84x / ~13.0% vs 2.17x / 16.8% gross — the gross-to-net gap widens the shortfall to a 20% gross hurdle.
A31: Source: Base = live model; Downside / Upside = documented judgment inputs (blue), see scenario logic at right. Exit net-cash overrides vs mechanical 2.0x/80% schedule (= +1.5bn / +2.6bn): Downside embeds remediation costs & trapped-cash risk.
A33: STRATEGIC-OWNER PERSPECTIVE — synergy walk to the 20% hurdle (illustrative)
C34: None | D34: Required | E34: Stretch
B35: Synergy EBITDA at exit (¥mm) | C35: 0 | D35: =C39 -> 244.00612 | E35: 500
B36: Supportable offer (¥/share) | C36: =((Returns!$C$9+Assumptions!$G$16*C35)/(1+Returns!$C$38)^Returns!$C$14+Sources_Uses!$G$5+Assumptions!$G$11-Assumptions!$G$10-Assumptions!$C$10)/Assumptions!$C$6 -> 2115.8849 | D36: =((Returns!$C$9+Assumptions!$G$16*D35)/(1+Returns!$C$38)^Returns!$C$14+Sources_Uses!$G$5+Assumptions!$G$11-Assumptions!$G$10-Assumptions!$C$10)/Assumptions!$C$6 -> 2301.6 | E36: =((Returns!$C$9+Assumptions!$G$16*E35)/(1+Returns!$C$38)^Returns!$C$14+Sources_Uses!$G$5+Assumptions!$G$11-Assumptions!$G$10-Assumptions!$C$10)/Assumptions!$C$6 -> 2496.4391
B37: Implied premium vs reference ¥1,680 | C37: =C36/Assumptions!$C$5-1 -> 0.25945531 | D37: =D36/Assumptions!$C$5-1 -> 0.37 | E37: =E36/Assumptions!$C$5-1 -> 0.48597563
B39: Synergy EBITDA required to support the full +37% offer (¥mm) | C39: =((Assumptions!C9+Assumptions!C10+Assumptions!G10-Sources_Uses!G5-Assumptions!G11)*(1+Returns!C38)^Returns!C14-Returns!C9)/Assumptions!G16 -> 244.00612 | D39: =C39/Model!J10 -> 0.17039167 | E39: of FY31E EBITDA (≈2.5% of FY31E revenue)
A41: Synergy sources for a mobility-platform owner (illustrative): HD-map licensing & maintenance for robotaxi ODDs · mapping-as-a-service for fleet operations · joint municipal AV-transport projects · Level-4 SI for platform pilots. Context: AISAN is a Tier IV shareholder (2017) and Autoware-ecosystem map partner (AutowareMaps, 2018; AV-taxi pilot 2019).
A42: Strategic premium discipline still applies — do not pay away 100% of synergies; gating DD (investigation, restatement, cash availability) is unchanged under a strategic lens.

Sheet Lev_Sensitivity
A1: 7 · LEVERAGE & FINANCING SENSITIVITY — illustrative only
A2: Interest held flat at 3.5%; 80% cash sweep per base financing policy; lender appetite / seasonality / investigation outcome unverified.
A4: Debt / EBITDA | B4: New debt | C4: Sponsor equity | D4: Exit equity | E4: MOIC | F4: IRR | G4: Ending debt | H4: Ending cash
A5: 1 | B5: =A5*Assumptions!$C$19 -> 800 | C5: =Assumptions!$C$9+Assumptions!$C$10+Assumptions!$G$10-B5-Assumptions!$G$11 -> 8452.8232 | D5: =Returns!$C$7+H19-G19 -> 17469.898 | E5: =D5/C5 -> 2.066753 | F5: =(D5/C5)^(1/Assumptions!$G$15)-1 -> 0.15626589 | G5: =G19 -> 0 | H5: =H19 -> 3149.5895
A6: 2 | B6: =A6*Assumptions!$C$19 -> 1600 | C6: =Assumptions!$C$9+Assumptions!$C$10+Assumptions!$G$10-B6-Assumptions!$G$11 -> 7652.8232 | D6: =Returns!$C$7+H28-G28 -> 16602.612 | E6: =D6/C6 -> 2.1694754 | F6: =(D6/C6)^(1/Assumptions!$G$15)-1 -> 0.16753779 | G6: =G28 -> 0 | H6: =H28 -> 2282.3034
A7: 2.5 | B7: =A7*Assumptions!$C$19 -> 2000 | C7: =Assumptions!$C$9+Assumptions!$C$10+Assumptions!$G$10-B7-Assumptions!$G$11 -> 7252.8232 | D7: =Returns!$C$7+H37-G37 -> 16157.876 | E7: =D7/C7 -> 2.227805 | F7: =(D7/C7)^(1/Assumptions!$G$15)-1 -> 0.17374954 | G7: =G37 -> 0 | H7: =H37 -> 1837.5677
A8: 3 | B8: =A8*Assumptions!$C$19 -> 2400 | C8: =Assumptions!$C$9+Assumptions!$C$10+Assumptions!$G$10-B8-Assumptions!$G$11 -> 6852.8232 | D8: =Returns!$C$7+H46-G46 -> 15707.673 | E8: =D8/C8 -> 2.2921463 | F8: =(D8/C8)^(1/Assumptions!$G$15)-1 -> 0.18045237 | G8: =G46 -> 10.108013 | H8: =H46 -> 1397.473
A11: Mini debt schedules
A13: 1.0x debt / EBITDA
A14: Fiscal year | B14: Beginning debt | C14: UFCF | D14: Cash interest | E14: FCF after interest | F14: Debt paydown | G14: Ending debt | H14: Ending cash
A15: FY27E | B15: =B5 -> 800 | C15: =Debt_FCF!F5*(1-Assumptions!$G$14)+Debt_FCF!F10+Debt_FCF!F11+Debt_FCF!F12 -> 476.20992 | D15: =B15*Assumptions!$G$7 -> 28 | E15: =C15-D15*(1-Assumptions!$G$14) -> 456.88992 | F15: =-MIN(B15,MAX(0,E15)*Assumptions!$G$8) -> -365.51194 | G15: =B15+F15 -> 434.48806 | H15: =Assumptions!$G$9+MAX(0,E15+F15) -> 891.37798
A16: FY28E | B16: =G15 -> 434.48806 | C16: =Debt_FCF!G5*(1-Assumptions!$G$14)+Debt_FCF!G10+Debt_FCF!G11+Debt_FCF!G12 -> 550.34752 | D16: =B16*Assumptions!$G$7 -> 15.207082 | E16: =C16-D16*(1-Assumptions!$G$14) -> 539.85463 | F16: =-MIN(B16,MAX(0,E16)*Assumptions!$G$8) -> -431.88371 | G16: =B16+F16 -> 2.6043574 | H16: =H15+MAX(0,E16+F16) -> 999.34891
A17: FY29E | B17: =G16 -> 2.6043574 | C17: =Debt_FCF!H5*(1-Assumptions!$G$14)+Debt_FCF!H10+Debt_FCF!H11+Debt_FCF!H12 -> 638.02385 | D17: =B17*Assumptions!$G$7 -> 0.091152509 | E17: =C17-D17*(1-Assumptions!$G$14) -> 637.96096 | F17: =-MIN(B17,MAX(0,E17)*Assumptions!$G$8) -> -2.6043574 | G17: =B17+F17 -> 0 | H17: =H16+MAX(0,E17+F17) -> 1634.7055
A18: FY30E | B18: =G17 -> 0 | C18: =Debt_FCF!I5*(1-Assumptions!$G$14)+Debt_FCF!I10+Debt_FCF!I11+Debt_FCF!I12 -> 715.55058 | D18: =B18*Assumptions!$G$7 -> 0 | E18: =C18-D18*(1-Assumptions!$G$14) -> 715.55058 | F18: =-MIN(B18,MAX(0,E18)*Assumptions!$G$8) -> 0 | G18: =B18+F18 -> 0 | H18: =H17+MAX(0,E18+F18) -> 2350.2561
A19: FY31E | B19: =G18 -> 0 | C19: =Debt_FCF!J5*(1-Assumptions!$G$14)+Debt_FCF!J10+Debt_FCF!J11+Debt_FCF!J12 -> 799.3334 | D19: =B19*Assumptions!$G$7 -> 0 | E19: =C19-D19*(1-Assumptions!$G$14) -> 799.3334 | F19: =-MIN(B19,MAX(0,E19)*Assumptions!$G$8) -> 0 | G19: =B19+F19 -> 0 | H19: =H18+MAX(0,E19+F19) -> 3149.5895
A22: 2.0x debt / EBITDA
A23: Fiscal year | B23: Beginning debt | C23: UFCF | D23: Cash interest | E23: FCF after interest | F23: Debt paydown | G23: Ending debt | H23: Ending cash
A24: FY27E | B24: =B6 -> 1600 | C24: =Debt_FCF!F5*(1-Assumptions!$G$14)+Debt_FCF!F10+Debt_FCF!F11+Debt_FCF!F12 -> 476.20992 | D24: =B24*Assumptions!$G$7 -> 56 | E24: =C24-D24*(1-Assumptions!$G$14) -> 437.56992 | F24: =-MIN(B24,MAX(0,E24)*Assumptions!$G$8) -> -350.05594 | G24: =B24+F24 -> 1249.9441 | H24: =Assumptions!$G$9+MAX(0,E24+F24) -> 887.51398
A25: FY28E | B25: =G24 -> 1249.9441 | C25: =Debt_FCF!G5*(1-Assumptions!$G$14)+Debt_FCF!G10+Debt_FCF!G11+Debt_FCF!G12 -> 550.34752 | D25: =B25*Assumptions!$G$7 -> 43.748042 | E25: =C25-D25*(1-Assumptions!$G$14) -> 520.16137 | F25: =-MIN(B25,MAX(0,E25)*Assumptions!$G$8) -> -416.1291 | G25: =B25+F25 -> 833.81497 | H25: =H24+MAX(0,E25+F25) -> 991.54626
A26: FY29E | B26: =G25 -> 833.81497 | C26: =Debt_FCF!H5*(1-Assumptions!$G$14)+Debt_FCF!H10+Debt_FCF!H11+Debt_FCF!H12 -> 638.02385 | D26: =B26*Assumptions!$G$7 -> 29.183524 | E26: =C26-D26*(1-Assumptions!$G$14) -> 617.88722 | F26: =-MIN(B26,MAX(0,E26)*Assumptions!$G$8) -> -494.30978 | G26: =B26+F26 -> 339.50519 | H26: =H25+MAX(0,E26+F26) -> 1115.1237
A27: FY30E | B27: =G26 -> 339.50519 | C27: =Debt_FCF!I5*(1-Assumptions!$G$14)+Debt_FCF!I10+Debt_FCF!I11+Debt_FCF!I12 -> 715.55058 | D27: =B27*Assumptions!$G$7 -> 11.882682 | E27: =C27-D27*(1-Assumptions!$G$14) -> 707.35153 | F27: =-MIN(B27,MAX(0,E27)*Assumptions!$G$8) -> -339.50519 | G27: =B27+F27 -> 0 | H27: =H26+MAX(0,E27+F27) -> 1482.97
A28: FY31E | B28: =G27 -> 0 | C28: =Debt_FCF!J5*(1-Assumptions!$G$14)+Debt_FCF!J10+Debt_FCF!J11+Debt_FCF!J12 -> 799.3334 | D28: =B28*Assumptions!$G$7 -> 0 | E28: =C28-D28*(1-Assumptions!$G$14) -> 799.3334 | F28: =-MIN(B28,MAX(0,E28)*Assumptions!$G$8) -> 0 | G28: =B28+F28 -> 0 | H28: =H27+MAX(0,E28+F28) -> 2282.3034
A31: 2.5x debt / EBITDA
A32: Fiscal year | B32: Beginning debt | C32: UFCF | D32: Cash interest | E32: FCF after interest | F32: Debt paydown | G32: Ending debt | H32: Ending cash
A33: FY27E | B33: =B7 -> 2000 | C33: =Debt_FCF!F5*(1-Assumptions!$G$14)+Debt_FCF!F10+Debt_FCF!F11+Debt_FCF!F12 -> 476.20992 | D33: =B33*Assumptions!$G$7 -> 70 | E33: =C33-D33*(1-Assumptions!$G$14) -> 427.90992 | F33: =-MIN(B33,MAX(0,E33)*Assumptions!$G$8) -> -342.32794 | G33: =B33+F33 -> 1657.6721 | H33: =Assumptions!$G$9+MAX(0,E33+F33) -> 885.58198
A34: FY28E | B34: =G33 -> 1657.6721 | C34: =Debt_FCF!G5*(1-Assumptions!$G$14)+Debt_FCF!G10+Debt_FCF!G11+Debt_FCF!G12 -> 550.34752 | D34: =B34*Assumptions!$G$7 -> 58.018522 | E34: =C34-D34*(1-Assumptions!$G$14) -> 510.31474 | F34: =-MIN(B34,MAX(0,E34)*Assumptions!$G$8) -> -408.25179 | G34: =B34+F34 -> 1249.4203 | H34: =H33+MAX(0,E34+F34) -> 987.64493
A35: FY29E | B35: =G34 -> 1249.4203 | C35: =Debt_FCF!H5*(1-Assumptions!$G$14)+Debt_FCF!H10+Debt_FCF!H11+Debt_FCF!H12 -> 638.02385 | D35: =B35*Assumptions!$G$7 -> 43.72971 | E35: =C35-D35*(1-Assumptions!$G$14) -> 607.85035 | F35: =-MIN(B35,MAX(0,E35)*Assumptions!$G$8) -> -486.28028 | G35: =B35+F35 -> 763.13999 | H35: =H34+MAX(0,E35+F35) -> 1109.215
A36: FY30E | B36: =G35 -> 763.13999 | C36: =Debt_FCF!I5*(1-Assumptions!$G$14)+Debt_FCF!I10+Debt_FCF!I11+Debt_FCF!I12 -> 715.55058 | D36: =B36*Assumptions!$G$7 -> 26.7099 | E36: =C36-D36*(1-Assumptions!$G$14) -> 697.12075 | F36: =-MIN(B36,MAX(0,E36)*Assumptions!$G$8) -> -557.6966 | G36: =B36+F36 -> 205.44339 | H36: =H35+MAX(0,E36+F36) -> 1248.6392
A37: FY31E | B37: =G36 -> 205.44339 | C37: =Debt_FCF!J5*(1-Assumptions!$G$14)+Debt_FCF!J10+Debt_FCF!J11+Debt_FCF!J12 -> 799.3334 | D37: =B37*Assumptions!$G$7 -> 7.1905187 | E37: =C37-D37*(1-Assumptions!$G$14) -> 794.37194 | F37: =-MIN(B37,MAX(0,E37)*Assumptions!$G$8) -> -205.44339 | G37: =B37+F37 -> 0 | H37: =H36+MAX(0,E37+F37) -> 1837.5677
A40: 3.0x debt / EBITDA
A41: Fiscal year | B41: Beginning debt | C41: UFCF | D41: Cash interest | E41: FCF after interest | F41: Debt paydown | G41: Ending debt | H41: Ending cash
A42: FY27E | B42: =B8 -> 2400 | C42: =Debt_FCF!F5*(1-Assumptions!$G$14)+Debt_FCF!F10+Debt_FCF!F11+Debt_FCF!F12 -> 476.20992 | D42: =B42*Assumptions!$G$7 -> 84 | E42: =C42-D42*(1-Assumptions!$G$14) -> 418.24992 | F42: =-MIN(B42,MAX(0,E42)*Assumptions!$G$8) -> -334.59994 | G42: =B42+F42 -> 2065.4001 | H42: =Assumptions!$G$9+MAX(0,E42+F42) -> 883.64998
A43: FY28E | B43: =G42 -> 2065.4001 | C43: =Debt_FCF!G5*(1-Assumptions!$G$14)+Debt_FCF!G10+Debt_FCF!G11+Debt_FCF!G12 -> 550.34752 | D43: =B43*Assumptions!$G$7 -> 72.289002 | E43: =C43-D43*(1-Assumptions!$G$14) -> 500.46811 | F43: =-MIN(B43,MAX(0,E43)*Assumptions!$G$8) -> -400.37449 | G43: =B43+F43 -> 1665.0256 | H43: =H42+MAX(0,E43+F43) -> 983.74361
A44: FY29E | B44: =G43 -> 1665.0256 | C44: =Debt_FCF!H5*(1-Assumptions!$G$14)+Debt_FCF!H10+Debt_FCF!H11+Debt_FCF!H12 -> 638.02385 | D44: =B44*Assumptions!$G$7 -> 58.275895 | E44: =C44-D44*(1-Assumptions!$G$14) -> 597.81348 | F44: =-MIN(B44,MAX(0,E44)*Assumptions!$G$8) -> -478.25079 | G44: =B44+F44 -> 1186.7748 | H44: =H43+MAX(0,E44+F44) -> 1103.3063
A45: FY30E | B45: =G44 -> 1186.7748 | C45: =Debt_FCF!I5*(1-Assumptions!$G$14)+Debt_FCF!I10+Debt_FCF!I11+Debt_FCF!I12 -> 715.55058 | D45: =B45*Assumptions!$G$7 -> 41.537118 | E45: =C45-D45*(1-Assumptions!$G$14) -> 686.88997 | F45: =-MIN(B45,MAX(0,E45)*Assumptions!$G$8) -> -549.51198 | G45: =B45+F45 -> 637.26281 | H45: =H44+MAX(0,E45+F45) -> 1240.6843
A46: FY31E | B46: =G45 -> 637.26281 | C46: =Debt_FCF!J5*(1-Assumptions!$G$14)+Debt_FCF!J10+Debt_FCF!J11+Debt_FCF!J12 -> 799.3334 | D46: =B46*Assumptions!$G$7 -> 22.304199 | E46: =C46-D46*(1-Assumptions!$G$14) -> 783.9435 | F46: =-MIN(B46,MAX(0,E46)*Assumptions!$G$8) -> -627.1548 | G46: =B46+F46 -> 10.108013 | H46: =H45+MAX(0,E46+F46) -> 1397.473
A49: FINANCING POLICY SENSITIVITY — at base leverage (2.0x) and base operating case
A50: Case | B50: MOIC | C50: IRR
A51: Cash sweep 80% of FCF (base) | B51: =E6 -> 2.1694754 | C51: =F6 -> 0.16753779
A52: Cash sweep 100% of FCF | B52: =(Returns!$C$7+H66-G66)/$C$6 -> 2.1713786 | C52: =B52^(1/Assumptions!$G$15)-1 -> 0.16774256
...
